<?xml version="1.0"?>
<!-- 
"""
MIT License

Copyright (c) 2023 Nipun Dhananjaya

Permission is hereby granted, free of charge, to any person obtaining a copy
of this software and associated documentation files (the "Software"), to deal
in the Software without restriction, including without limitation the rights
to use, copy, modify, merge, publish, distribute, sublicense, and/or sell
copies of the Software, and to permit persons to whom the Software is
furnished to do so, subject to the following conditions:

The above copyright notice and this permission notice shall be included in all
copies or substantial portions of the Software.

THE SOFTWARE IS PROVIDED "AS IS", WITHOUT WARRANTY OF ANY KIND, EXPRESS OR
IMPLIED, INCLUDING BUT NOT LIMITED TO THE WARRANTIES OF MERCHANTABILITY,
FITNESS FOR A PARTICULAR PURPOSE AND NONINFRINGEMENT. IN NO EVENT SHALL THE
AUTHORS OR COPYRIGHT HOLDERS BE LIABLE FOR ANY CLAIM, DAMAGES OR OTHER
LIABILITY, WHETHER IN AN ACTION OF CONTRACT, TORT OR OTHERWISE, ARISING FROM,
OUT OF OR IN CONNECTION WITH THE SOFTWARE OR THE USE OR OTHER DEALINGS IN THE
SOFTWARE.
"""
 -->
<robot name="meshes/hyperdog_v2" xmlns:xacro="http://www.ros.org/wiki/xacro">

<xacro:property name="hip_low_limit"  value="-1.57"/>
<xacro:property name="hip_up_limit"   value="1.57"/>
<xacro:property name="uleg_low_limit" value="-1.2217"/>
<xacro:property name="uleg_up_limit"  value="3.14"/>
<xacro:property name="lleg_low_limit" value="-1.57"/>
<xacro:property name="lleg_up_limit"  value="2.618"/>
<xacro:property name="velocity"       value="7"/>
<xacro:property name="effort"         value="8"/>
<xacro:property name="body_mass" value="3"/>
<xacro:property name="hip_mass" value="0.3"/>
<xacro:property name="uleg_mass" value="0.5"/>
<xacro:property name="lleg_mass" value="0.2"/>
<!-- configure inertia -->


<!-- materials -->
  <material name="black">
    <color rgba="0.0 0.0 0.0 1.0"/>
  </material>
  <material name="blue">
    <color rgba="0.0 0.0 0.8 1.0"/>
  </material>
  <material name="green">
    <color rgba="0.0 0.8 0.0 1.0"/>
  </material>
  <material name="grey">
    <color rgba="0.2 0.2 0.2 1.0"/>
  </material>
  <material name="silver">
    <color rgba="0.913725490196 0.913725490196 0.847058823529 1.0"/>
  </material>
  <material name="orange">
    <color rgba="1.0 0.423529411765 0.0392156862745 1.0"/>
  </material>
  <material name="brown">
    <color rgba="0.870588235294 0.811764705882 0.764705882353 1.0"/>
  </material>
  <material name="red">
    <color rgba="0.8 0.0 0.0 1.0"/>
  </material>
  <material name="white">
    <color rgba="1.0 1.0 1.0 1.0"/>
  </material>

<!-- 
<link name="world"/>
<joint name="float_joint" type="floating">
    <parent link="world"/>
    <child link="base_link"/>
</joint> -->

<!-- base link -->
<link name="base_link">
    <visual>
        <origin xyz="0 0 0" rpy="0 0 0"/>
        <geometry>
            <mesh filename="../meshes/hyperdog_v2/body.stl" scale="0.001 0.001 0.001"/>
        </geometry>
        <material name="silver"/>
    </visual>
    <collision>
        <origin xyz="0 0 0" rpy="0 0 0"/>
        <geometry>
            <mesh filename="../meshes/hyperdog_v2/body.stl" scale="0.001 0.001 0.001"/>
        </geometry>
    </collision>
    <inertial>
        <origin xyz="-0.006 0.00633 0.00214" rpy="0 0 0"/> 
        <mass value="3"/>
        <inertia  ixx="0.011396658109874464" ixy="0" ixz="0" iyy="0.05486450023370329" iyz="0" izz="0.06098759357764758" />   
    </inertial>
</link>

<!-- *********** FR_hip LINK *********** -->
<link name="FR_hip_link">
    <visual>
        <origin xyz="0 0 0" rpy="0 0 0"/>
        <geometry>
            <mesh filename="../meshes/hyperdog_v2/RIGHT_HIP.stl" scale="0.001 0.001 0.001"/>
        </geometry>
        <material name="grey"/>
    </visual>
    <collision>
        <origin xyz="0 0 0" rpy="0 0 0"/>
        <geometry>
            <mesh filename="../meshes/hyperdog_v2/RIGHT_HIP.stl" scale="0.001 0.001 0.001"/>
        </geometry>
    </collision>
    <inertial>
        <origin xyz="0.0 -0.02 0.01" rpy="0 0 0"/>
        <mass value="0.3" />
        <inertia  ixx="0.000785664594069212" ixy="0" ixz="0" iyy="0.00028126771524959764" iyz="0" izz="0.0007138119943369485" />
    </inertial>
</link>

<!-- *********** FL_hip LINK ********** -->
<link name="FL_hip_link">
    <visual>
        <origin xyz="0 0 0" rpy="0 0 0"/>
        <geometry>
            <mesh filename="../meshes/hyperdog_v2/LEFT_HIP.stl" scale="0.001 0.001 0.001"/>
        </geometry>
        <material name="grey"/>
    </visual>
    <collision>
        <origin xyz="0 0 0" rpy="0 0 0"/>
        <geometry>
            <mesh filename="../meshes/hyperdog_v2/LEFT_HIP.stl" scale="0.001 0.001 0.001"/>
        </geometry>
    </collision>
    <inertial>
        <origin xyz="0.0 0.02 0.01" rpy="0 0 0"/>
        <mass value="0.3" />
        <inertia  ixx="0.000785664594069212" ixy="0" ixz="0" iyy="0.00028126771524959764" iyz="0" izz="0.0007138119943369485" />
    </inertial>
</link>

<!-- *********** BR_hip LINK ********** -->
<link name="BR_hip_link">
    <visual>
        <origin xyz="0 0 0" rpy="0 0 0"/>
        <geometry>
            <mesh filename="../meshes/hyperdog_v2/RIGHT_HIP.stl" scale="0.001 0.001 0.001"/>
        </geometry>
        <material name="grey"/>
    </visual>
    <collision>
        <origin xyz="0 0 0" rpy="0 0 0"/>
        <geometry>
            <mesh filename="../meshes/hyperdog_v2/RIGHT_HIP.stl" scale="0.001 0.001 0.001"/>
        </geometry>
    </collision>
    <inertial>
        <origin xyz="0.0 -0.02 0.01" rpy="0 0 0"/>
        <mass value="0.3" />
        <inertia  ixx="0.000785664594069212" ixy="0" ixz="0" iyy="0.00028126771524959764" iyz="0" izz="0.0007138119943369485" />
    </inertial>
</link>

<!-- *********** BL_hip LINK ********** -->
<link name="BL_hip_link">
    <visual>
        <origin xyz="0 0 0" rpy="0 0 0"/>
        <geometry>
            <mesh filename="../meshes/hyperdog_v2/LEFT_HIP.stl" scale="0.001 0.001 0.001"/>
        </geometry>
        <material name="grey"/>
    </visual>
    <collision>
        <origin xyz="0 0 0" rpy="0 0 0"/>
        <geometry>
            <mesh filename="../meshes/hyperdog_v2/LEFT_HIP.stl" scale="0.001 0.001 0.001"/>
        </geometry>
    </collision>
    <inertial>
        <origin xyz="0.0 0.02 0.01" rpy="0 0 0"/>
        <mass value="0.3" />
        <inertia  ixx="0.000785664594069212" ixy="0" ixz="0" iyy="0.00028126771524959764" iyz="0" izz="0.0007138119943369485" />
    </inertial>
</link>

<!-- *********** FR_uleg ********** -->
<link name="FR_uleg_link">
    <visual>
        <origin xyz="0 0 0" rpy="0 0 0"/>
        <geometry>                
            <mesh filename="../meshes/hyperdog_v2/RIGHT_ULEG.stl" scale="0.001 0.001 0.001"/>
        </geometry>
        <material name="grey"/>
    </visual>
    <collision>
        <origin xyz="0 0 0" rpy="0 0 0"/>
        <geometry>
            <mesh filename="../meshes/hyperdog_v2/RIGHT_ULEG.stl" scale="0.001 0.001 0.001"/>
        </geometry>
    </collision>
    <inertial>
        <origin xyz="-0.02 0.02 0.0" rpy="0 0 0"/>
        <mass value="0.5" />
        <inertia  ixx="0.0005320036781441746" ixy="0" ixz="0" iyy="0.00178632152356757" iyz="0" izz="0.002124721126775121" />
    </inertial>
</link>

<!-- *********** FL_uleg ********** -->
<link name="FL_uleg_link">
    <visual>
        <origin xyz="0 0 0" rpy="0 0 0"/>
        <geometry>                
            <mesh filename="../meshes/hyperdog_v2/LEFT_ULEG.stl" scale="0.001 0.001 0.001"/>
        </geometry>
        <material name="grey"/>
    </visual>
    <collision>
        <origin xyz="0 0 0" rpy="0 0 0"/>
        <geometry>
            <mesh filename="../meshes/hyperdog_v2/LEFT_ULEG.stl" scale="0.001 0.001 0.001"/>
        </geometry>
    </collision>
    <inertial>
        <origin xyz="-0.02 -0.02 0.0" rpy="0 0 0"/>
        <mass value="0.5"/>
        <inertia  ixx="0.0005320036934665719" ixy="0" ixz="0" iyy="0.0017863215388899672" iyz="0" izz="0.002124721126775121" />
    </inertial>
</link>

<!-- *********** BR_uleg ********** -->
<link name="BR_uleg_link">
    <visual>
        <origin xyz="0 0 0" rpy="0 0 0"/>
        <geometry>                
            <mesh filename="../meshes/hyperdog_v2/RIGHT_ULEG.stl" scale="0.001 0.001 0.001"/>
        </geometry>
        <material name="grey"/>
    </visual>
    <collision>
        <origin xyz="0 0 0" rpy="0 0 0"/>
        <geometry>
            <mesh filename="../meshes/hyperdog_v2/RIGHT_ULEG.stl" scale="0.001 0.001 0.001"/>
        </geometry>
    </collision>
    <inertial>
        <origin xyz="-0.02 0.02 0.0" rpy="0 0 0"/>
        <mass value="0.5" />
        <inertia  ixx="0.0005320036781441746" ixy="0" ixz="0" iyy="0.00178632152356757" iyz="0" izz="0.002124721126775121" />
    </inertial>
</link>

<!-- *********** BL_uleg ********** -->
<link name="BL_uleg_link">
    <visual>
        <origin xyz="0 0 0" rpy="0 0 0"/>
        <geometry>                
            <mesh filename="../meshes/hyperdog_v2/LEFT_ULEG.stl" scale="0.001 0.001 0.001"/>
        </geometry>
        <material name="grey"/>
    </visual>
    <collision>
        <origin xyz="0 0 0" rpy="0 0 0"/>
        <geometry>
            <mesh filename="../meshes/hyperdog_v2/LEFT_ULEG.stl" scale="0.001 0.001 0.001"/>
        </geometry>
    </collision>
    <inertial>
        <origin xyz="-0.02 -0.02 0.0" rpy="0 0 0"/>
        <mass value="0.5"/>
        <inertia  ixx="0.0005320036934665719" ixy="0" ixz="0" iyy="0.0017863215388899672" iyz="0" izz="0.002124721126775121" />
    </inertial>
</link>

<!-- *********** FR_lleg ********** -->
<link name="FR_lleg_link">
    <visual>
        <origin xyz="0 0 0" rpy="0 0 0"/>
        <geometry>                
            <mesh filename="../meshes/hyperdog_v2/LLEG.stl" scale="0.001 0.001 0.001"/>
        </geometry>
        <material name="brown"/>
    </visual>
    <collision>
        <origin xyz="0 0 0" rpy="0 0 0"/>
        <geometry>
            <mesh filename="../meshes/hyperdog_v2/LLEG.stl" scale="0.001 0.001 0.001"/>
        </geometry>
    </collision>
    <inertial>
        <origin xyz="0.05 0.0 0.0" rpy="0 0 0"/>
        <mass value="0.2" />
        <inertia  ixx="6.323427512607013e-05" ixy="0" ixz="0" iyy="0.0006549703843792289" iyz="0" izz="0.0006232548592531587" />
    </inertial>
</link>

<!-- *********** FL_lleg ********** -->
<link name="FL_lleg_link">
    <visual>
        <origin xyz="0 0 0" rpy="0 0 0"/>
        <geometry>                
            <mesh filename="../meshes/hyperdog_v2/LLEG.stl" scale="0.001 0.001 0.001"/>
        </geometry>
        <material name="brown"/>
    </visual>
    <collision>
        <origin xyz="0 0 0" rpy="0 0 0"/>
        <geometry>
            <mesh filename="../meshes/hyperdog_v2/LLEG.stl" scale="0.001 0.001 0.001"/>
        </geometry>
    </collision>
    <inertial>
        <origin xyz="0.05 0.0 0.0" rpy="0 0 0"/>
        <mass value="0.2" />
        <inertia  ixx="6.323427512607013e-05" ixy="0" ixz="0" iyy="0.0006549703843792289" iyz="0" izz="0.0006232548592531587" />
    </inertial>
</link>

<!-- *********** BR_lleg ********** -->
<link name="BR_lleg_link">
    <visual>
        <origin xyz="0 0 0" rpy="0 0 0"/>
        <geometry>                
            <mesh filename="../meshes/hyperdog_v2/LLEG.stl" scale="0.001 0.001 0.001"/>
        </geometry>
        <material name="brown"/>
    </visual>
    <collision>
        <origin xyz="0 0 0" rpy="0 0 0"/>
        <geometry>
            <mesh filename="../meshes/hyperdog_v2/LLEG.stl" scale="0.001 0.001 0.001"/>
        </geometry>
    </collision>
    <inertial>
        <origin xyz="0.05 0.0 0.0" rpy="0 0 0"/>
        <mass value="0.2" />
        <inertia  ixx="6.323427512607013e-05" ixy="0" ixz="0" iyy="0.0006549703843792289" iyz="0" izz="0.0006232548592531587" />
    </inertial>
</link>

<!-- *********** BL_lleg ********** -->
<link name="BL_lleg_link">
    <visual>
        <origin xyz="0 0 0" rpy="0 0 0"/>
        <geometry>                
            <mesh filename="../meshes/hyperdog_v2/LLEG.stl" scale="0.001 0.001 0.001"/>
        </geometry>
        <material name="brown"/>
    </visual>
    <collision>
        <origin xyz="0 0 0" rpy="0 0 0"/>
        <geometry>
            <mesh filename="../meshes/hyperdog_v2/LLEG.stl" scale="0.001 0.001 0.001"/>
        </geometry>
    </collision>
    <inertial>
        <origin xyz="0.05 0.0 0.0" rpy="0 0 0"/>
        <mass value="0.2" />
        <inertia  ixx="6.323427512607013e-05" ixy="0" ixz="0" iyy="0.0006549703843792289" iyz="0" izz="0.0006232548592531587" />
    </inertial>
</link>



<!-- *********  FR_hip  JOINT ********* -->
<joint name="FR_hip_joint" type="revolute">
    <axis xyz="-1 0 0" rpy="0 0 0"/>
    <origin xyz="0.175 -0.066 0" rpy="0 0 0"/>
    <parent link="base_link"/>
    <child link="FR_hip_link"/>
    <limit lower="-1.57" upper="1.57" velocity="7" effort="8"/>
    <dynamics damping="0" friction="0"/>
</joint>

<!-- *********  FL_hip JOINT ********* -->
<joint name="FL_hip_joint" type="revolute">
    <axis xyz="1 0 0"/>
    <origin xyz="0.175 0.066 0" rpy="0 0 0"/>
    <parent link="base_link"/>
    <child link="FL_hip_link"/>
    <limit lower="-1.57" upper="1.57" velocity="7" effort="8"/>
    <dynamics damping="0" friction="0"/>
</joint>

<!-- *********  BR_hip JOINT ********* -->
<joint name="BR_hip_joint" type="revolute">
    <axis xyz="-1 0 0"/>
    <origin xyz="-0.175 -0.066 0" rpy="0 0 0"/>
    <parent link="base_link"/>
    <child link="BR_hip_link"/>
    <limit lower="-1.57" upper="1.57" velocity="7" effort="8"/>
    <dynamics damping="0" friction="0"/>
</joint>

<!-- *********  BL_hip JOINT ********* -->
<joint name="BL_hip_joint" type="revolute">
    <axis xyz="1 0 0"/>
    <origin xyz="-0.175 0.066 0" rpy="0 0 0"/>
    <parent link="base_link"/>
    <child link="BL_hip_link"/>
    <limit lower="-1.57" upper="1.57" velocity="7" effort="8"/>
    <dynamics damping="0" friction="0"/>
</joint>


<!-- *********  FR_uleg joint ********* -->
<joint name="FR_uleg_joint" type="revolute">
    <axis xyz="0 -1 0"/>
    <origin xyz="0 -0.104 0" rpy="0 0 0"/>
    <parent link="FR_hip_link"/>
    <child link="FR_uleg_link"/>
    <limit lower="-1.2217" upper="3.14" velocity="7" effort="8"/>
    <dynamics damping="0" friction="0"/>
</joint>


<!-- *********  FL_uleg  ********* -->
<joint name="FL_uleg_joint" type="revolute">
    <axis xyz="0 -1 0"/>
    <origin xyz="0 0.104 0" rpy="0 0 0"/>
    <parent link="FL_hip_link"/>
    <child link="FL_uleg_link"/>
    <limit lower="-1.2217" upper="3.14" velocity="7" effort="8"/>
    <dynamics damping="0" friction="0"/>
</joint>


<!-- *********  BR_uleg  ********* -->
<joint name="BR_uleg_joint" type="revolute">
    <axis xyz="0 -1 0"/>
    <origin xyz="0 -0.104 0" rpy="0 0 0"/>
    <parent link="BR_hip_link"/>
    <child link="BR_uleg_link"/>
    <limit lower="-1.2217" upper="3.14" velocity="7" effort="8"/>
    <dynamics damping="0" friction="0"/>
</joint>


 <!-- *********  BL_uleg  ********* -->
<joint name="BL_uleg_joint" type="revolute">
    <axis xyz="0 -1 0"/>
    <origin xyz="0 0.104 0" rpy="0 0 0"/>
    <parent link="BL_hip_link"/>
    <child link="BL_uleg_link"/>
    <limit lower="-1.2217" upper="3.14" velocity="7" effort="8"/>
    <dynamics damping="0" friction="0"/>
</joint>

<!-- *********  FR_lleg  ********* -->
<joint name="FR_lleg_joint" type="revolute">
    <axis xyz="0 1 0"/>
    <origin xyz="-0.15 0 0" rpy="0 0 0"/>
    <parent link="FR_uleg_link"/>
    <child link="FR_lleg_link"/>
    <limit lower="0.5235987755982988" upper="2.9670597283903604" velocity="7" effort="8"/>
    <dynamics damping="0" friction="0"/>
</joint>


<!-- *********  FL_lleg  ********* -->
<joint name="FL_lleg_joint" type="revolute">
    <axis xyz="0 1 0"/>
    <origin xyz="-0.15 0 0" rpy="0 0 0"/>
    <parent link="FL_uleg_link"/>
    <child link="FL_lleg_link"/>
    <limit lower="0.5235987755982988" upper="2.9670597283903604" velocity="7" effort="8"/>
    <dynamics damping="0" friction="0"/>
</joint>


<!-- *********  BR_lleg  ********* -->
<joint name="BR_lleg_joint" type="revolute">
    <origin xyz="-0.15 0 0" rpy="0 0 0"/>
    <parent link="BR_uleg_link"/>
    <child link="BR_lleg_link"/>
    <axis xyz="0 1 0"/>
    <limit lower="0.5235987755982988" upper="2.9670597283903604" velocity="7" effort="8"/>
    <dynamics damping="0" friction="0"/>
</joint>


<!-- *********  BL_lleg  ********* -->
<joint name="BL_lleg_joint" type="revolute">
    <axis xyz="0 1 0"/>
    <origin xyz="-0.15 0 0" rpy="0 0 0"/>
    <parent link="BL_uleg_link"/>
    <child link="BL_lleg_link"/>
    <limit lower="0.5235987755982988" upper="2.9670597283903604" velocity="7" effort="8"/>
    <dynamics damping="0" friction="0"/>
</joint>

</robot>